Traceback (most recent call last):
  File "/Users/johannes/opt/anaconda3/envs/books/lib/python3.8/site-packages/jupyter_cache/executors/utils.py", line 51, in single_nb_execution
    executenb(
  File "/Users/johannes/opt/anaconda3/envs/books/lib/python3.8/site-packages/nbclient/client.py", line 1204, in execute
    return NotebookClient(nb=nb, resources=resources, km=km, **kwargs).execute()
  File "/Users/johannes/opt/anaconda3/envs/books/lib/python3.8/site-packages/nbclient/util.py", line 84, in wrapped
    return just_run(coro(*args, **kwargs))
  File "/Users/johannes/opt/anaconda3/envs/books/lib/python3.8/site-packages/nbclient/util.py", line 62, in just_run
    return loop.run_until_complete(coro)
  File "/Users/johannes/opt/anaconda3/envs/books/lib/python3.8/asyncio/base_events.py", line 608, in run_until_complete
    return future.result()
  File "/Users/johannes/opt/anaconda3/envs/books/lib/python3.8/site-packages/nbclient/client.py", line 663, in async_execute
    await self.async_execute_cell(
  File "/Users/johannes/opt/anaconda3/envs/books/lib/python3.8/site-packages/nbclient/client.py", line 965, in async_execute_cell
    await self._check_raise_for_error(cell, cell_index, exec_reply)
  File "/Users/johannes/opt/anaconda3/envs/books/lib/python3.8/site-packages/nbclient/client.py", line 862, in _check_raise_for_error
    raise CellExecutionError.from_cell_and_msg(cell, exec_reply_content)
nbclient.exceptions.CellExecutionError: An error occurred while executing the following cell:
------------------
import numpy as np
from scipy.stats import multivariate_normal
from matplotlib import pyplot as plt
from matplotlib import cm
_ =gauss2d()
------------------

[0;31m---------------------------------------------------------------------------[0m
[0;31mTypeError[0m                                 Traceback (most recent call last)
[0;32m/var/folders/68/9tltm6l520v0stj3qjlc5v9w0000gn/T/ipykernel_24047/2468790525.py[0m in [0;36m<module>[0;34m[0m
[1;32m      3[0m [0;32mfrom[0m [0mmatplotlib[0m [0;32mimport[0m [0mpyplot[0m [0;32mas[0m [0mplt[0m[0;34m[0m[0;34m[0m[0m
[1;32m      4[0m [0;32mfrom[0m [0mmatplotlib[0m [0;32mimport[0m [0mcm[0m[0;34m[0m[0;34m[0m[0m
[0;32m----> 5[0;31m [0m_[0m [0;34m=[0m[0mgauss2d[0m[0;34m([0m[0;34m)[0m[0;34m[0m[0;34m[0m[0m
[0m
[0;32m/var/folders/68/9tltm6l520v0stj3qjlc5v9w0000gn/T/ipykernel_24047/3923805391.py[0m in [0;36mgauss2d[0;34m(mu, sigma)[0m
[1;32m     16[0m [0;34m[0m[0m
[1;32m     17[0m     [0mfig[0m [0;34m=[0m [0mplt[0m[0;34m.[0m[0mfigure[0m[0;34m([0m[0mfigsize[0m[0;34m=[0m[0;34m([0m[0;36m10[0m[0;34m,[0m[0;36m10[0m[0;34m)[0m[0;34m)[0m[0;34m[0m[0;34m[0m[0m
[0;32m---> 18[0;31m     [0max[0m [0;34m=[0m [0mfig[0m[0;34m.[0m[0mgca[0m[0;34m([0m[0mprojection[0m[0;34m=[0m[0;34m'3d'[0m[0;34m)[0m[0;34m[0m[0;34m[0m[0m
[0m[1;32m     19[0m     [0max[0m[0;34m.[0m[0mplot_surface[0m[0;34m([0m[0mx[0m[0;34m,[0m [0my[0m[0;34m,[0m [0mz[0m[0;34m.[0m[0mT[0m[0;34m,[0m[0mrstride[0m[0;34m=[0m[0;36m3[0m[0;34m,[0m [0mcstride[0m[0;34m=[0m[0;36m3[0m[0;34m,[0m [0mlinewidth[0m[0;34m=[0m[0;36m1[0m[0;34m,[0m [0mantialiased[0m[0;34m=[0m[0;32mTrue[0m[0;34m,[0m[0mcmap[0m[0;34m=[0m[0mcm[0m[0;34m.[0m[0mviridis[0m[0;34m)[0m[0;34m[0m[0;34m[0m[0m
[1;32m     20[0m     [0mplt[0m[0;34m.[0m[0mxlabel[0m[0;34m([0m[0;34m"x"[0m[0;34m)[0m[0;34m[0m[0;34m[0m[0m

[0;31mTypeError[0m: gca() got an unexpected keyword argument 'projection'
TypeError: gca() got an unexpected keyword argument 'projection'

